Workbook

Sheet Articles per publication year
A1: {=_xlfn.UNIQUE(VALUE(RIGHT(Articles[Publication year], 4)))} -> 2025 | B1: =COUNTIF(Articles[Publication year], "*" & A1) -> 16 | D1: {=_xlfn._xlws.SORT(A1:B6,1)} -> 2021 | E1: 2
A2: 2022 | B2: =COUNTIF(Articles[Publication year], "*" & A2) -> 7 | D2: 2022 | E2: 7
A3: 2024 | B3: =COUNTIF(Articles[Publication year], "*" & A3) -> 9 | D3: 2023 | E3: 4
A4: 2026 | B4: =COUNTIF(Articles[Publication year], "*" & A4) -> 15 | D4: 2024 | E4: 9
A5: 2021 | B5: =COUNTIF(Articles[Publication year], "*" & A5) -> 2 | D5: 2025 | E5: 16
A6: 2023 | B6: =COUNTIF(Articles[Publication year], "*" & A6) -> 4 | D6: 2026 | E6: 15

Sheet Articles per publisher
A1: {=TRIM(_xlfn.TEXTBEFORE(Articles[Repository, journal/proceeding, and publisher],", "))} -> Scopus | B1: {=TRIM(_xlfn.TEXTBEFORE(_xlfn.TEXTAFTER(Articles[Repository, journal/proceeding, and publisher], ",", 1), ",", -1))} -> Baltic Journal of Modern Computing | C1: {=TRIM(_xlfn.TEXTAFTER(Articles[Repository, journal/proceeding, and publisher], ",", -1))} -> University of Latvia | E1: {=_xlfn.UNIQUE(_xlfn.ANCHORARRAY(A1))} -> Scopus | F1: =COUNTIF(_xlfn.ANCHORARRAY($A$1),E1) -> 40 | H1: {=_xlfn._xlws.SORT(E1:F6,2,-1)} -> Scopus | I1: 40 | K1: {=_xlfn.UNIQUE(_xlfn.ANCHORARRAY(B1))} -> Baltic Journal of Modern Computing | L1: =COUNTIF(_xlfn.ANCHORARRAY($B$1),K1) -> 1 | N1: {=_xlfn.UNIQUE(_xlfn.ANCHORARRAY(C1))} -> University of Latvia | O1: =COUNTIF(_xlfn.ANCHORARRAY($C$1),N1) -> 1 | Q1: {=_xlfn._xlws.SORT(N1:O20,2,-1)} -> IEEE | R1: 14 | T1: =Q1 -> IEEE | U1: =R1 -> 14
A2: Scopus | B2: Neural Computing and Applications | C2: Springer Nature | E2: IEEE Xplore | F2: =COUNTIF(_xlfn.ANCHORARRAY($A$1),E2) -> 3 | H2: SBC OpenLib | I2: 7 | K2: Neural Computing and Applications | L2: =COUNTIF(_xlfn.ANCHORARRAY($B$1),K2) -> 1 | N2: Springer Nature | O2: =COUNTIF(_xlfn.ANCHORARRAY($C$1),N2) -> 5 | Q2: SBC | R2: 7 | T2: =Q2 -> SBC | U2: =R2 -> 7
A3: Scopus | B3: The International Arab Journal of Information Technology (IAJIT) | C3: Zarqa University | E3: ACM Digital Library | F3: =COUNTIF(_xlfn.ANCHORARRAY($A$1),E3) -> 1 | H3: IEEE Xplore | I3: 3 | K3: The International Arab Journal of Information Technology (IAJIT) | L3: =COUNTIF(_xlfn.ANCHORARRAY($B$1),K3) -> 1 | N3: Zarqa University | O3: =COUNTIF(_xlfn.ANCHORARRAY($C$1),N3) -> 1 | Q3: Springer Nature | R3: 5 | T3: =Q3 -> Springer Nature | U3: =R3 -> 5
A4: Scopus | B4: SN Computer Science | C4: Springer Nature | E4: Web of Science | F4: =COUNTIF(_xlfn.ANCHORARRAY($A$1),E4) -> 1 | H4: ACM Digital Library | I4: 1 | K4: SN Computer Science | L4: =COUNTIF(_xlfn.ANCHORARRAY($B$1),K4) -> 1 | N4: Zenodo | O4: =COUNTIF(_xlfn.ANCHORARRAY($C$1),N4) -> 1 | Q4: MDPI | R4: 5 | T4: =Q4 -> MDPI | U4: =R4 -> 5
A5: Scopus | B5: Discover Artificial Intelligence | C5: Springer Nature | E5: Springer Link | F5: =COUNTIF(_xlfn.ANCHORARRAY($A$1),E5) -> 1 | H5: Web of Science | I5: 1 | K5: Discover Artificial Intelligence | L5: =COUNTIF(_xlfn.ANCHORARRAY($B$1),K5) -> 1 | N5: Inderscience Publishers | O5: =COUNTIF(_xlfn.ANCHORARRAY($C$1),N5) -> 1 | Q5: Elsevier | R5: 4 | T5: =Q5 -> Elsevier | U5: =R5 -> 4
A6: Scopus | B6: Journal of Educational Data Mining | C6: Zenodo | E6: SBC OpenLib | F6: =COUNTIF(_xlfn.ANCHORARRAY($A$1),E6) -> 7 | H6: Springer Link | I6: 1 | K6: Journal of Educational Data Mining | L6: =COUNTIF(_xlfn.ANCHORARRAY($B$1),K6) -> 1 | N6: IEEE | O6: =COUNTIF(_xlfn.ANCHORARRAY($C$1),N6) -> 14 | Q6: ACM | R6: 3 | T6: =Q6 -> ACM | U6: =R6 -> 3
A7: Scopus | B7: International Journal of Information and Communication Technology | C7: Inderscience Publishers | K7: International Journal of Information and Communication Technology | L7: =COUNTIF(_xlfn.ANCHORARRAY($B$1),K7) -> 1 | N7: MDPI | O7: =COUNTIF(_xlfn.ANCHORARRAY($C$1),N7) -> 5 | Q7: PeerJ | R7: 2 | T7: =Q7 -> PeerJ | U7: =R7 -> 2
A8: Scopus | B8: 2024 International Conference on Electronics, Computing, Communication and Control Technology (ICECCC) | C8: IEEE | K8: 2024 International Conference on Electronics, Computing, Communication and Control Technology (ICECCC) | L8: =COUNTIF(_xlfn.ANCHORARRAY($B$1),K8) -> 1 | N8: Elsevier | O8: =COUNTIF(_xlfn.ANCHORARRAY($C$1),N8) -> 4 | Q8: University of Latvia | R8: 1 | T8: Others | U8: =SUM(R8:R20) -> 13
A9: Scopus | B9: IEEE Access | C9: IEEE | K9: IEEE Access | L9: =COUNTIF(_xlfn.ANCHORARRAY($B$1),K9) -> 2 | N9: PeerJ | O9: =COUNTIF(_xlfn.ANCHORARRAY($C$1),N9) -> 2 | Q9: Zarqa University | R9: 1
A10: Scopus | B10: electronics | C10: MDPI | K10: electronics | L10: =COUNTIF(_xlfn.ANCHORARRAY($B$1),K10) -> 1 | N10: Hindawi | O10: =COUNTIF(_xlfn.ANCHORARRAY($C$1),N10) -> 1 | Q10: Zenodo | R10: 1
A11: Scopus | B11: Computers and Electrical Engineering | C11: Elsevier | K11: Computers and Electrical Engineering | L11: =COUNTIF(_xlfn.ANCHORARRAY($B$1),K11) -> 1 | N11: SPIE | O11: =COUNTIF(_xlfn.ANCHORARRAY($C$1),N11) -> 1 | Q11: Inderscience Publishers | R11: 1
A12: Scopus | B12: Journal of Ambient Intelligence and Humanized Computing | C12: Springer Nature | K12: Journal of Ambient Intelligence and Humanized Computing | L12: =COUNTIF(_xlfn.ANCHORARRAY($B$1),K12) -> 1 | N12: Bright | O12: =COUNTIF(_xlfn.ANCHORARRAY($C$1),N12) -> 1 | Q12: Hindawi | R12: 1
A13: Scopus | B13: Mathematics | C13: MDPI | K13: Mathematics | L13: =COUNTIF(_xlfn.ANCHORARRAY($B$1),K13) -> 1 | N13: International Educational Data Mining Society | O13: =COUNTIF(_xlfn.ANCHORARRAY($C$1),N13) -> 1 | Q13: SPIE | R13: 1
A14: Scopus | B14: IEEE Transactions on Big Data | C14: IEEE | K14: IEEE Transactions on Big Data | L14: =COUNTIF(_xlfn.ANCHORARRAY($B$1),K14) -> 1 | N14: IGI Global Scientific Publishing | O14: =COUNTIF(_xlfn.ANCHORARRAY($C$1),N14) -> 1 | Q14: Bright | R14: 1
A15: Scopus | B15: PeerJ Computer Science | C15: PeerJ | K15: PeerJ Computer Science | L15: =COUNTIF(_xlfn.ANCHORARRAY($B$1),K15) -> 2 | N15: Science Publications | O15: =COUNTIF(_xlfn.ANCHORARRAY($C$1),N15) -> 1 | Q15: International Educational Data Mining Society | R15: 1
A16: Scopus | B16: IEEE Access | C16: IEEE | K16: Mobile Information Systems | L16: =COUNTIF(_xlfn.ANCHORARRAY($B$1),K16) -> 1 | N16: SciEngine | O16: =COUNTIF(_xlfn.ANCHORARRAY($C$1),N16) -> 1 | Q16: IGI Global Scientific Publishing | R16: 1
A17: Scopus | B17: Mobile Information Systems | C17: Hindawi | K17: International Conference on Algorithms, Image Processing, and Deep Learning (AIPDL 2025) | L17: =COUNTIF(_xlfn.ANCHORARRAY($B$1),K17) -> 1 | N17: ACM | O17: =COUNTIF(_xlfn.ANCHORARRAY($C$1),N17) -> 3 | Q17: Science Publications | R17: 1
A18: Scopus | B18: International Conference on Algorithms, Image Processing, and Deep Learning (AIPDL 2025) | C18: SPIE | K18: Applied Sciences | L18: =COUNTIF(_xlfn.ANCHORARRAY($B$1),K18) -> 2 | N18: Emeral Publishing Limited | O18: =COUNTIF(_xlfn.ANCHORARRAY($C$1),N18) -> 1 | Q18: SciEngine | R18: 1
A19: Scopus | B19: Applied Sciences | C19: MDPI | K19: 2025 IEEE Frontiers in Education Conference (FIE) | L19: =COUNTIF(_xlfn.ANCHORARRAY($B$1),K19) -> 1 | N19: SBC | O19: =COUNTIF(_xlfn.ANCHORARRAY($C$1),N19) -> 7 | Q19: Emeral Publishing Limited | R19: 1
A20: Scopus | B20: PeerJ Computer Science | C20: PeerJ | K20: Journal of Applied Sciences (JADS) | L20: =COUNTIF(_xlfn.ANCHORARRAY($B$1),K20) -> 1 | N20: Noves Ricerca | O20: =COUNTIF(_xlfn.ANCHORARRAY($C$1),N20) -> 1 | Q20: Noves Ricerca | R20: 1
A21: Scopus | B21: 2025 IEEE Frontiers in Education Conference (FIE) | C21: IEEE | K21: 16th International Conference on Educational Data Mining | L21: =COUNTIF(_xlfn.ANCHORARRAY($B$1),K21) -> 1
A22: Scopus | B22: Journal of Applied Sciences (JADS) | C22: Bright | K22: International Journal of e-Collaboration | L22: =COUNTIF(_xlfn.ANCHORARRAY($B$1),K22) -> 1
A23: Scopus | B23: 16th International Conference on Educational Data Mining | C23: International Educational Data Mining Society | K23: 2022 IEEE 4th International Conference on Cognitive Machine Intelligence (CogMI) | L23: =COUNTIF(_xlfn.ANCHORARRAY($B$1),K23) -> 1
A24: Scopus | B24: International Journal of e-Collaboration | C24: IGI Global Scientific Publishing | K24: Journal of Computer Science | L24: =COUNTIF(_xlfn.ANCHORARRAY($B$1),K24) -> 1
A25: Scopus | B25: 2022 IEEE 4th International Conference on Cognitive Machine Intelligence (CogMI) | C25: IEEE | K25: Computers and Education: Artificial Intelligence | L25: =COUNTIF(_xlfn.ANCHORARRAY($B$1),K25) -> 2
A26: Scopus | B26: Journal of Computer Science | C26: Science Publications | K26: Data Intelligence | L26: =COUNTIF(_xlfn.ANCHORARRAY($B$1),K26) -> 1
A27: Scopus | B27: Applied Sciences | C27: MDPI | K27: 2025 International Conference on Data Science, Agents & Artificial Intelligence (ICDSAAI) | L27: =COUNTIF(_xlfn.ANCHORARRAY($B$1),K27) -> 1
A28: Scopus | B28: Computers and Education: Artificial Intelligence | C28: Elsevier | K28: Expert Systems With Applications | L28: =COUNTIF(_xlfn.ANCHORARRAY($B$1),K28) -> 1
A29: Scopus | B29: Data Intelligence | C29: SciEngine | K29: Data | L29: =COUNTIF(_xlfn.ANCHORARRAY($B$1),K29) -> 1
A30: IEEE Xplore | B30: 2025 International Conference on Data Science, Agents & Artificial Intelligence (ICDSAAI) | C30: IEEE | K30: ISAIE '24: Proceedings of the 2024 International Symposium on Artificial Intelligence for Education | L30: =COUNTIF(_xlfn.ANCHORARRAY($B$1),K30) -> 1
A31: Scopus | B31: Computers and Education: Artificial Intelligence | C31: Elsevier | K31: UMAP '25: Proceedings of the 33rd ACM Conference on User Modeling, Adaptation and Personalization | L31: =COUNTIF(_xlfn.ANCHORARRAY($B$1),K31) -> 1
A32: Scopus | B32: Expert Systems With Applications | C32: Elsevier | K32: 2025 3rd International Conference on Artificial Intelligence and Machine Learning Applications Theme: Healthcare and Internet of Things (AIMLA) | L32: =COUNTIF(_xlfn.ANCHORARRAY($B$1),K32) -> 1
... A48: SBC OpenLib | B48: 2024: Anais do XXXII Workshop sobre Educação em Computação | C48: SBC | K48: 2026 IEEE 2nd International Conference on Electronics, Energy Systems and Power Engineering (EESPE) | L48: =COUNTIF(_xlfn.ANCHORARRAY($B$1),K48) -> 1
A49: SBC OpenLib | B49: 2026: Anais da XXI Escola Regional de Banco de Dados | C49: SBC
A50: IEEE Xplore | B50: 2026 4th International Conference on Sustainable Computing and Smart Systems (ICSCSS) | C50: IEEE
A51: Scopus | B51: 2026 International Conference on Intelligent Engineering and Next-Gen Healthcare Systems (IEHNS) | C51: IEEE
A52: Scopus | B52: Journal of Intelligent Decision Making and Information Science | C52: Noves Ricerca
A53: Scopus | B53: 2026 IEEE 2nd International Conference on Electronics, Energy Systems and Power Engineering (EESPE) | C53: IEEE

Sheet Articles per Author's Country
A1: {=_xlfn.UNIQUE(Articles[Country of the first author’s institution])} -> Latvia | B1: =COUNTIF(Articles[Country of the first author’s institution],A1) -> 1 | D1: {=_xlfn._xlws.SORT(A1:B18,2,-1)} -> China | E1: 15
A2: Pakistan | B2: =COUNTIF(Articles[Country of the first author’s institution],A2) -> 1 | D2: India | E2: 9
A3: China | B3: =COUNTIF(Articles[Country of the first author’s institution],A3) -> 15 | D3: Brazil | E3: 7
A4: Vietnam | B4: =COUNTIF(Articles[Country of the first author’s institution],A4) -> 2 | D4: United States | E4: 5
A5: Germany | B5: =COUNTIF(Articles[Country of the first author’s institution],A5) -> 2 | D5: Vietnam | E5: 2
A6: India | B6: =COUNTIF(Articles[Country of the first author’s institution],A6) -> 9 | D6: Germany | E6: 2
A7: Romania | B7: =COUNTIF(Articles[Country of the first author’s institution],A7) -> 1 | D7: Morocco | E7: 2
A8: Spain | B8: =COUNTIF(Articles[Country of the first author’s institution],A8) -> 1 | D8: Latvia | E8: 1
A9: Serbia | B9: =COUNTIF(Articles[Country of the first author’s institution],A9) -> 1 | D9: Pakistan | E9: 1
A10: Cyprus | B10: =COUNTIF(Articles[Country of the first author’s institution],A10) -> 1 | D10: Romania | E10: 1
A11: Russia | B11: =COUNTIF(Articles[Country of the first author’s institution],A11) -> 1 | D11: Spain | E11: 1
A12: United States | B12: =COUNTIF(Articles[Country of the first author’s institution],A12) -> 5 | D12: Serbia | E12: 1
A13: Indonesia | B13: =COUNTIF(Articles[Country of the first author’s institution],A13) -> 1 | D13: Cyprus | E13: 1
... A18: Australia | B18: =COUNTIF(Articles[Country of the first author’s institution],A18) -> 1 | D18: Australia | E18: 1

Sheet Articles per Student Features
B1: {=TRANSPOSE(_xlfn.UNIQUE(Articles[Teaching environment]))} -> Online | C1: In-person | D1: Hybrid
A2: {=_xlfn._xlws.SORT(_xlfn.UNIQUE(TRIM(_xlfn.TOCOL(_xlfn.TEXTSPLIT(_xlfn.TEXTJOIN(",", TRUE, Articles[Type of student data used for training]), ",")))))} -> Academic records | B2: =COUNTIFS(Articles[[Type of student data used for training]:[Type of student data used for training]], "*" & 'Articles per Student Features'!$A2 & "*", Articles[[Teaching environment]:[Teaching environment]], 'Articles per Student Features'!B$1) -> 13 | C2: =COUNTIFS(Articles[[Type of student data used for training]:[Type of student data used for training]], "*" & 'Articles per Student Features'!$A2 & "*", Articles[[Teaching environment]:[Teaching environment]], 'Articles per Student Features'!C$1) -> 22 | D2: =COUNTIFS(Articles[[Type of student data used for training]:[Type of student data used for training]], "*" & 'Articles per Student Features'!$A2 & "*", Articles[[Teaching environment]:[Teaching environment]], 'Articles per Student Features'!D$1) -> 9
A3: Demographic data | B3: =COUNTIFS(Articles[[Type of student data used for training]:[Type of student data used for training]], "*" & 'Articles per Student Features'!$A3 & "*", Articles[[Teaching environment]:[Teaching environment]], 'Articles per Student Features'!B$1) -> 10 | C3: =COUNTIFS(Articles[[Type of student data used for training]:[Type of student data used for training]], "*" & 'Articles per Student Features'!$A3 & "*", Articles[[Teaching environment]:[Teaching environment]], 'Articles per Student Features'!C$1) -> 16 | D3: =COUNTIFS(Articles[[Type of student data used for training]:[Type of student data used for training]], "*" & 'Articles per Student Features'!$A3 & "*", Articles[[Teaching environment]:[Teaching environment]], 'Articles per Student Features'!D$1) -> 4
A4: Knowledge component | B4: =COUNTIFS(Articles[[Type of student data used for training]:[Type of student data used for training]], "*" & 'Articles per Student Features'!$A4 & "*", Articles[[Teaching environment]:[Teaching environment]], 'Articles per Student Features'!B$1) -> 0 | C4: =COUNTIFS(Articles[[Type of student data used for training]:[Type of student data used for training]], "*" & 'Articles per Student Features'!$A4 & "*", Articles[[Teaching environment]:[Teaching environment]], 'Articles per Student Features'!C$1) -> 1 | D4: =COUNTIFS(Articles[[Type of student data used for training]:[Type of student data used for training]], "*" & 'Articles per Student Features'!$A4 & "*", Articles[[Teaching environment]:[Teaching environment]], 'Articles per Student Features'!D$1) -> 0
A5: Multi-modal data | B5: =COUNTIFS(Articles[[Type of student data used for training]:[Type of student data used for training]], "*" & 'Articles per Student Features'!$A5 & "*", Articles[[Teaching environment]:[Teaching environment]], 'Articles per Student Features'!B$1) -> 1 | C5: =COUNTIFS(Articles[[Type of student data used for training]:[Type of student data used for training]], "*" & 'Articles per Student Features'!$A5 & "*", Articles[[Teaching environment]:[Teaching environment]], 'Articles per Student Features'!C$1) -> 4 | D5: =COUNTIFS(Articles[[Type of student data used for training]:[Type of student data used for training]], "*" & 'Articles per Student Features'!$A5 & "*", Articles[[Teaching environment]:[Teaching environment]], 'Articles per Student Features'!D$1) -> 1
A6: VLE activity log | B6: =COUNTIFS(Articles[[Type of student data used for training]:[Type of student data used for training]], "*" & 'Articles per Student Features'!$A6 & "*", Articles[[Teaching environment]:[Teaching environment]], 'Articles per Student Features'!B$1) -> 16 | C6: =COUNTIFS(Articles[[Type of student data used for training]:[Type of student data used for training]], "*" & 'Articles per Student Features'!$A6 & "*", Articles[[Teaching environment]:[Teaching environment]], 'Articles per Student Features'!C$1) -> 0 | D6: =COUNTIFS(Articles[[Type of student data used for training]:[Type of student data used for training]], "*" & 'Articles per Student Features'!$A6 & "*", Articles[[Teaching environment]:[Teaching environment]], 'Articles per Student Features'!D$1) -> 4

Sheet Articles per Architecture
B1: {=TRANSPOSE(_xlfn.UNIQUE(Articles[Teaching environment]))} -> Online | C1: In-person | D1: Hybrid
A2: {=_xlfn.UNIQUE(Articles[Machine learning architecture])} -> Deep learning | B2: =COUNTIFS(Articles[[Machine learning architecture]:[Machine learning architecture]],$A2,Articles[[Teaching environment]:[Teaching environment]],B$1) -> 10 | C2: =COUNTIFS(Articles[[Machine learning architecture]:[Machine learning architecture]],$A2,Articles[[Teaching environment]:[Teaching environment]],C$1) -> 5 | D2: =COUNTIFS(Articles[[Machine learning architecture]:[Machine learning architecture]],$A2,Articles[[Teaching environment]:[Teaching environment]],D$1) -> 1 | F2: =B2/SUM(B$2:B$5) -> 0.52631579 | G2: =C2/SUM(C$2:C$5) -> 0.20833333 | H2: =D2/SUM(D$2:D$5) -> 0.1
A3: Ensemble learning | B3: =COUNTIFS(Articles[[Machine learning architecture]:[Machine learning architecture]],$A3,Articles[[Teaching environment]:[Teaching environment]],B$1) -> 6 | C3: =COUNTIFS(Articles[[Machine learning architecture]:[Machine learning architecture]],$A3,Articles[[Teaching environment]:[Teaching environment]],C$1) -> 9 | D3: =COUNTIFS(Articles[[Machine learning architecture]:[Machine learning architecture]],$A3,Articles[[Teaching environment]:[Teaching environment]],D$1) -> 4 | F3: =B3/SUM(B$2:B$5) -> 0.31578947 | G3: =C3/SUM(C$2:C$5) -> 0.375 | H3: =D3/SUM(D$2:D$5) -> 0.4
A4: Reinforcement learning | B4: =COUNTIFS(Articles[[Machine learning architecture]:[Machine learning architecture]],$A4,Articles[[Teaching environment]:[Teaching environment]],B$1) -> 1 | C4: =COUNTIFS(Articles[[Machine learning architecture]:[Machine learning architecture]],$A4,Articles[[Teaching environment]:[Teaching environment]],C$1) -> 2 | D4: =COUNTIFS(Articles[[Machine learning architecture]:[Machine learning architecture]],$A4,Articles[[Teaching environment]:[Teaching environment]],D$1) -> 0 | F4: =B4/SUM(B$2:B$5) -> 0.052631579 | G4: =C4/SUM(C$2:C$5) -> 0.083333333 | H4: =D4/SUM(D$2:D$5) -> 0
A5: Machine learning | B5: =COUNTIFS(Articles[[Machine learning architecture]:[Machine learning architecture]],$A5,Articles[[Teaching environment]:[Teaching environment]],B$1) -> 2 | C5: =COUNTIFS(Articles[[Machine learning architecture]:[Machine learning architecture]],$A5,Articles[[Teaching environment]:[Teaching environment]],C$1) -> 8 | D5: =COUNTIFS(Articles[[Machine learning architecture]:[Machine learning architecture]],$A5,Articles[[Teaching environment]:[Teaching environment]],D$1) -> 5 | F5: =B5/SUM(B$2:B$5) -> 0.10526316 | G5: =C5/SUM(C$2:C$5) -> 0.33333333 | H5: =D5/SUM(D$2:D$5) -> 0.5

Sheet Articles per Limitations
B1: {=TRANSPOSE(_xlfn.UNIQUE(Articles[Teaching environment]))} -> Online | C1: In-person | D1: Hybrid
A2: {=_xlfn._xlws.SORT(_xlfn.UNIQUE(TRIM(_xlfn.TOCOL(_xlfn.TEXTSPLIT(_xlfn.TEXTJOIN(",", TRUE, Articles[ [ Types of reported barriers or limitations] ]), ",")))))} -> Class imbalance | B2: =COUNTIFS(Articles[[ Types of reported barriers or limitations]:[ Types of reported barriers or limitations]], "*" & 'Articles per Limitations'!$A2 & "*", Articles[[Teaching environment]:[Teaching environment]], 'Articles per Limitations'!B$1) -> 6 | C2: =COUNTIFS(Articles[[ Types of reported barriers or limitations]:[ Types of reported barriers or limitations]], "*" & 'Articles per Limitations'!$A2 & "*", Articles[[Teaching environment]:[Teaching environment]], 'Articles per Limitations'!C$1) -> 7 | D2: =COUNTIFS(Articles[[ Types of reported barriers or limitations]:[ Types of reported barriers or limitations]], "*" & 'Articles per Limitations'!$A2 & "*", Articles[[Teaching environment]:[Teaching environment]], 'Articles per Limitations'!D$1) -> 3
A3: Data availability | B3: =COUNTIFS(Articles[[ Types of reported barriers or limitations]:[ Types of reported barriers or limitations]], "*" & 'Articles per Limitations'!$A3 & "*", Articles[[Teaching environment]:[Teaching environment]], 'Articles per Limitations'!B$1) -> 5 | C3: =COUNTIFS(Articles[[ Types of reported barriers or limitations]:[ Types of reported barriers or limitations]], "*" & 'Articles per Limitations'!$A3 & "*", Articles[[Teaching environment]:[Teaching environment]], 'Articles per Limitations'!C$1) -> 5 | D3: =COUNTIFS(Articles[[ Types of reported barriers or limitations]:[ Types of reported barriers or limitations]], "*" & 'Articles per Limitations'!$A3 & "*", Articles[[Teaching environment]:[Teaching environment]], 'Articles per Limitations'!D$1) -> 4
A4: Model generalization | B4: =COUNTIFS(Articles[[ Types of reported barriers or limitations]:[ Types of reported barriers or limitations]], "*" & 'Articles per Limitations'!$A4 & "*", Articles[[Teaching environment]:[Teaching environment]], 'Articles per Limitations'!B$1) -> 9 | C4: =COUNTIFS(Articles[[ Types of reported barriers or limitations]:[ Types of reported barriers or limitations]], "*" & 'Articles per Limitations'!$A4 & "*", Articles[[Teaching environment]:[Teaching environment]], 'Articles per Limitations'!C$1) -> 11 | D4: =COUNTIFS(Articles[[ Types of reported barriers or limitations]:[ Types of reported barriers or limitations]], "*" & 'Articles per Limitations'!$A4 & "*", Articles[[Teaching environment]:[Teaching environment]], 'Articles per Limitations'!D$1) -> 2
A5: Privacy concerns | B5: =COUNTIFS(Articles[[ Types of reported barriers or limitations]:[ Types of reported barriers or limitations]], "*" & 'Articles per Limitations'!$A5 & "*", Articles[[Teaching environment]:[Teaching environment]], 'Articles per Limitations'!B$1) -> 5 | C5: =COUNTIFS(Articles[[ Types of reported barriers or limitations]:[ Types of reported barriers or limitations]], "*" & 'Articles per Limitations'!$A5 & "*", Articles[[Teaching environment]:[Teaching environment]], 'Articles per Limitations'!C$1) -> 3 | D5: =COUNTIFS(Articles[[ Types of reported barriers or limitations]:[ Types of reported barriers or limitations]], "*" & 'Articles per Limitations'!$A5 & "*", Articles[[Teaching environment]:[Teaching environment]], 'Articles per Limitations'!D$1) -> 3
A6: Resource overhead | B6: =COUNTIFS(Articles[[ Types of reported barriers or limitations]:[ Types of reported barriers or limitations]], "*" & 'Articles per Limitations'!$A6 & "*", Articles[[Teaching environment]:[Teaching environment]], 'Articles per Limitations'!B$1) -> 2 | C6: =COUNTIFS(Articles[[ Types of reported barriers or limitations]:[ Types of reported barriers or limitations]], "*" & 'Articles per Limitations'!$A6 & "*", Articles[[Teaching environment]:[Teaching environment]], 'Articles per Limitations'!C$1) -> 3 | D6: =COUNTIFS(Articles[[ Types of reported barriers or limitations]:[ Types of reported barriers or limitations]], "*" & 'Articles per Limitations'!$A6 & "*", Articles[[Teaching environment]:[Teaching environment]], 'Articles per Limitations'!D$1) -> 2
A7: Result interpretability | B7: =COUNTIFS(Articles[[ Types of reported barriers or limitations]:[ Types of reported barriers or limitations]], "*" & 'Articles per Limitations'!$A7 & "*", Articles[[Teaching environment]:[Teaching environment]], 'Articles per Limitations'!B$1) -> 1 | C7: =COUNTIFS(Articles[[ Types of reported barriers or limitations]:[ Types of reported barriers or limitations]], "*" & 'Articles per Limitations'!$A7 & "*", Articles[[Teaching environment]:[Teaching environment]], 'Articles per Limitations'!C$1) -> 4 | D7: =COUNTIFS(Articles[[ Types of reported barriers or limitations]:[ Types of reported barriers or limitations]], "*" & 'Articles per Limitations'!$A7 & "*", Articles[[Teaching environment]:[Teaching environment]], 'Articles per Limitations'!D$1) -> 0

Sheet Articles
A1: article | B1: DOI (unique identifier) | C1: Author(s) | D1: Publication year | E1: Repository, journal/proceeding, and publisher | F1: Country of the first author’s institution | G1: Main contributions of the study | H1: Sample size (number of students) | I1: Teaching environment | J1: Features collected from monitored students | K1: Type of student data used for training | L1: Prediction models applied | M1: Machine learning architecture | N1: Evaluated models' performance metrics | O1: Results: Technical and/or pedagogical improvements | P1: Reported barriers or limitations | Q1: Types of reported barriers or limitations | R1: Ethical and privacy considerations
A2: Predicting Student Performance on a Novel Moodle Dataset Using GRU Time Series Model | B2: 10.22364/bjmc.2025.13.4.07 | C2: Sneiders, Martins and Urtans, Evalds and Abu Saa, Amjed | D2: 2025 | E2: Scopus, Baltic Journal of Modern Computing, University of Latvia | F2: Latvia | G2: The main contribution of this paper is the dataset provided by the University of Latvia, which comprises over 1.259.411 student activity logs and 20.317 final grade records from a Moodle virtual learning environment across an academic semester. Made publicly available on Kaggle, this dataset was used to train a GRU-based predictive model. | H2: Tables 2 and 3: The dataset contained records for 6.990 students from the University of Latvia. Model validation (testing) used a 20% random sample, while training used the remaining 80%. The model was trained to classify students into 11 grade categories ranging from 0 to 10. The dataset also included a group of students with a grade of -1, representing unrecorded grades. The initial training iteration—using activity logs alone—proved ineffective; thus, the final model was trained on a subset of 216 courses (3,5%) that included assigned final grades. | I2: Online | J2: User activity logs, including logins, chapter access, response submissions, and posted course assessments, along with student final course grades for the semester. | K2: Academic records, VLE activity log | L2: The predictive model applied was based on Gated Recurrent Units (GRU), with the experiment focusing on classifying students into one of 11 grade groups based on their dropout risk. | M2: Deep learning | N2: Accuracy. | O2: The model achieved an accuracy of 83% when integrating intermediate grades (Figure 1), compared to 80% when using only user activity data (Figure 2). | P2: The authors report that the dataset contained data from only a single academic semester and suggest integrating additional semesters in future studies. Furthermore, the majority of activity logs were generated by less than 5% of users and were concentrated in just a few courses, primarily those related to information technology. The authors also highlight a severe class imbalance in the dataset, where 76,1% of the grades fall within the 8–10 range, whereas only 4,6% represent lower grades (0–3). Consequently, they recommend exploring additional error and calibration metrics in future research. | Q2: Class imbalance, Model generalization, Privacy concerns | R2: The dataset was obtained under a non-disclosure agreement with the university. For future research, the authors highlight privacy-preserving collaborative approaches—such as federated learning—to avoid exposing raw data while potentially enhancing model generalization.
A3: Introducing the Hyperdynamic Adaptive Learning Fusion (HALF) model for superior predictive analytics in E-learning | B3: 10.1007/s00521-025-11018-7 | C3: Islam, Umar and Alali, Ibrahim Khalil and Alotaibi, Shoayee Dlaim and Alzaid, Zaid and Shah, Babar and Ali, Ijaz and Moreira, Fernando | D3: March 13, 2025 | E3: Scopus, Neural Computing and Applications, Springer Nature | F3: Pakistan | G3: The development of the Hyperdynamic Adaptive Learning Fusion (HALF) leverages a fusion strategy that integrates a base model, focused on capturing general behavior patterns, and an adaptive model, capable of identifying contextual nuances and temporal variables. This architecture allows for greater efficiency despite the heterogeneous and dynamic nature of educational data, incorporating feedback loops for continuous self-adjustment of the learning process of new students in real time. In addition to processing large volumes of programmatic content, the HALF model employs advanced techniques to deeply understand the student's interaction-affect-performance profile. The model actively seeks to mitigate biases to ensure equal opportunities for students of different ethnic backgrounds. Furthermore, it was designed to operate in synergy with current learning management systems, seeking to maximize accessibility and usability for instructors. | H3: The dataset was extracted from the Open University Virtual Learning Environment and contains approximately 500.000 records of roughly 170.000 students across multiple courses and academic years. The features were chosen based on their relevance for predicting student outcomes, given that previous research demonstrated that factors such as demographic and behavioral data are intimately related to performance. Finally, the dataset was partitioned into training, validation, and test sets using an 80/10/10 ratio. | I3: Online | J3: Table 1: The variables include demographic data—location, age, disabilities, educational level, and gender—as well as performance indicators: assignment grades and virtual learning environment interaction metrics. The preprocessing involved imputing missing numerical values using the mean or median, using the mode for categorical variables, removing records with excessive missing values, and normalizing continuous variables (performance indicators). For categorical variables, one-hot encoding was employed to ensure that the model processes this information efficiently, without introducing artificial hierarchies or biases. Conversely, continuous variables were handled using interquartile range (IQR) analysis for outlier identification and removal, preventing extreme values from distorting system performance and learning. | K3: Academic records, Demographic data, VLE activity log | L3: The HALF model is based on the combination of two models via an optimized fusion parameter. First, a base model is trained on the entire dataset to learn general patterns—employing the Bagging technique, which consists of training multiple instances of the model on random partitions of the dataset to reduce variance, making predictions more stable and resistant to noise. Second, an adaptive model is designed to identify contextual and time-sensitive patterns—capturing rapid changes in engagement that static models overlook—by employing the Boosting technique, which trains the model sequentially to reduce errors of previous iterations, focusing on hard-to-predict cases and reducing overall system bias. To mitigate overfitting, L2 regularization and dropout techniques were employed, and training was stopped early when performance stagnated. | M3: Ensemble learning | N3: Accuracy, Precision, Recall, and F1-Score. The proposed model was benchmarked against conventional models (e.g., SVM and KNN), as well as standalone architectures of only-bagging and only-boosting. | O3: Table 6: The model demonstrated superior results when compared to the baseline models: 87% accuracy, 85% precision, 84% recall, and an 84% F1-Score. On the other hand, the HALF model required a higher training time (215 seconds). Table 4: The model performance decreased—and training time increased—as the dataset size grew. Furthermore, the proposed model presented a superior performance in the in-person environment compared to the online environment (Table 5). Results also indicated that frequent student interaction with the VLE platform is strongly positively correlated with higher assessment scores. | P3: The continuous tuning and training process increased the system's computational complexity. Bagging and Boosting techniques require intensive computational resources—thus the author's alert to potential latency impacts and computational overhead during real-time operations, suggesting that future research explore distributed computing and parallel processing. | Q3: Resource overhead, Result interpretability | R3: Despite not discussing the informed consent for the dataset employed, the authors addressed interpretability, bias reduction, and equity in the proposed model.
A4: Cognitive-Fuzzy Learning System-Based University English Smart Classroom Teaching Design and Application | B4: 10.34028/iajit/23/4/13 | C4: Lai, Ningyi | D4: December 8, 2025 | E4: Scopus, The International Arab Journal of Information Technology (IAJIT), Zarqa University | F4: China | G4: Propose the Cognitive-Fuzzy Adaptive Learning Algorithm (CFALA), a novel hybrid architecture combining cognitive psychology (ACT-R) with fuzzy logic (ANFIS) and reinforcement learning (Q-learning) for personalized, real-time classroom adaptation. Designed a comprehensive smart classroom framework containing 5 interconnected modules: Data Collection, Cognitive Processing, Fuzzy Inference Engine, Adaptive Strategy Generator, and Smart Classroom Interface. Demonstrated empirical superiority of CFALA over three state-of-the-art alternative frameworks across student engagement, learning outcomes, responsiveness, and feedback accuracy. | H4: Table 2: 500 students, 20 classes, and 25 staff monitored over 1 academic semester (16 weeks). | I4: In-person | J4: Student Interactions (Real-Time): touchscreens, keyboards, voice, classroom participation, online activity, peer collaborations. Performance Metrics (Daily/Weekly): quizzes, assignments, participation, grades, language proficiency tests. Learning Patterns (Continuous): task logs, resource access, time spent on activities, preferred learning resources, learning speed, and intensity. Environmental Data (Real-Time): IoT sensors monitoring classroom temperature, noise levels, lighting, and time of day. Student Demographics: age range, language backgrounds, and prior English proficiency levels. | K4: Academic records, Demographic data, Multi-modal data | L4: ACT-R (Adaptive Control of Thought-Rational): Cognitive architecture modeling procedural memory, declarative memory, goal buffer, and perceptual-motor modules. ANFIS (Adaptive Neuro-Fuzzy Inference System): Integrates neural networks with fuzzy logic to handle data ambiguity and uncertainties. Computes rule firing strength and performs defuzzification via the Centroid Method. Q-Learning Algorithm: Reinforcement learning for iterative teaching strategy optimization. | M4: Reinforcement learning | N4: Student Engagement Score; Learning Outcome Improvement Rate (%); Time to Skill Mastery; User Satisfaction Score; System Responsiveness: Adaptation Speed, Adaptation Accuracy, and Real-time Feedback Delay; System Scalability: Max users, latency, adaptation accuracy, and resource utilization; Real-Time Feedback Accuracy (%). | O4: Table 5: Real-Time Feedback Accuracy: CFALA achieved 95,43%, significantly outperforming CFBLS (87,49%), ANFLM (83,28%), and DAA-UC (79,23%). Learning Outcome Improvement: CFALA consistently achieved the highest improvement rates (~90% to over 100%) across vocabulary, grammar, reading, writing, and overall English compared to baselines. Table 3: System Responsiveness: Adaptation speed was <1 second with 92% adaptation accuracy and immediate real-time feedback (compared to 1,5–3 seconds latency in baseline systems). Table 4: Scalability: Handled 500+ students/class with <1 second latency and optimized resource utilization of <80% (Excellent rating). User Satisfaction: Consistently highest stacked satisfaction ratings across ease of use, perceived effectiveness, learning support, feedback quality, and overall satisfaction. | P4: Data Stream Instability: Heavy reliance on the continuous stability and precision of high-speed, real-time data streams. Manual Rules Setup: Scaling is technically constrained due to the high subject-matter expertise required to manually set up, tune, and refine the fuzzy logic rule base. Generalizability Limits: Currently optimized only for ESL/EFL contexts; broadening to STEM or other areas requires developing domain-specific cognitive and fuzzy models. | Q4: Model generalization, Privacy concerns, Resource overhead, Result interpretability | R4: Data Privacy: Massive real-time data extraction of student behavior, interactions, and biometric indicators presents data privacy risks. Algorithmic Bias: Potential for feedback bias within the adaptive decision-making and reward structures. Lack of Transparency: The "black box" nature of combining complex neural networks (ANFIS) and cognitive architectures raises concerns regarding the transparency of pedagogical decisions.
A5: A Hybrid Approach Using Decision Tree and Multiple Linear Regression for Predicting Students’ Performance Based on Learning Progress and Behavior | B5: 10.1007/s42979-022-01251-5 | C5: Dang, Tran Khanh and Nguyen, Huu Huong Xuan | D5: July 25, 2022 | E5: Scopus, SN Computer Science, Springer Nature | F5: Vietnam | G5: A hybrid approach combining decision trees for qualitative classification of academic performance with multiple linear regression to predict final GPA. | H5: The dataset comprises 326 student records, featuring 40 variables from a higher education institution in the Sultanate of Oman. The data was collected from three primary sources: a Student Information System (SIS), a Learning Management System (LMS)—Moodle—and a video interaction platform (eDity). It covers the period from Spring 2017 to Spring 2021. | I5: Hybrid | J5: The variables include coursework grades for assignments 1 and 2, final exam scores, and indicators for whether a student has failed two or more modules, as well as the failure rate in a specific module. They also track the total number of module attempts, enrollment in the student success center due to academic deficiencies, probation status based on delayed modules, and registration in multiple modules during the current semester. Additionally, the dataset records whether a student studies remotely, their progression rate along the degree plan, and their level of online activity both on and off campus. Video engagement metrics capture play counts, pause frequencies, video likes, and the frequency of replaying specific video segments. Finally, it accounts for any history of academic integrity violations across modules. | K5: Academic records, VLE activity log | L5: Decision Tree for qualitative classification and Multiple Linear Regression for grade prediction. | M5: Machine learning | N5: The performance of the Decision Tree model was evaluated using a Confusion Matrix, Accuracy, Precision, and Recall, while Multiple Linear Regression was assessed using R-Squared, Correlation Coefficient (CC), Mean Absolute Error (MAE), Root Mean Squared Error (RMSE), Relative Absolute Error (RAE), and Root Relative Squared Error (RRSE). | O5: For the Decision Tree model (Table 6), the overall accuracy was 0,472. Class-level precision values were 0,66 for Excellent, 0,528 for Adequate, and 0,17 for Fair, whereas recall values reached 0,631 for Adequate, 0,419 for Good, and 0,326 for Fair. For Multiple Linear Regression (Table 7), the model achieved an R-Squared of 0,316 and a correlation coefficient of 0,5263, with error metrics of MAE = 0,4119, RMSE = 0,5191, RAE = 83,16%, and RRSE = 85,03%. | P5: The authors acknowledged that the accuracy of the proposed model remains low compared to previous studies, a limitation they intend to address in future work. Specifically, the authors noted that using only 17 features resulted in an overly simplistic decision tree. To overcome this, future research should explore alternative classification methods alongside a broader set of evaluation metrics, moving beyond the sole reliance on accuracy. | Q5: Data availability | R5: The dataset included the applicant name field, which suggests that the information was not anonymized.
A6: Research on the refinement of college student education management based on artificial intelligence | B6: 10.1007/s44163-025-00651-9 | C6: Lai, Qiujia | D6: December 12, 2025 | E6: Scopus, Discover Artificial Intelligence, Springer Nature | F6: China | G6: The proposed hybrid model, AGTO-ResRNN, was designed to predict student performance and risk. AGTO was employed for efficient parameter optimization, enhancing convergence and generalization, while ResRNN captured complex sequential patterns from students' behavioral and academic records through residual recurrent learning. This framework enables accurate risk prediction, performance evaluation, and personalized support in academic management using minimal labeled data. | H6: The dataset comprised 1.200 anonymized student records, each featuring 15 attributes, obtained from the Kaggle platform. | I6: Online | J6: Figure 3: The dataset includes students' academic outcomes and behavioral patterns, along with demographic information, such as age, GPA, course load, average grade in curricular components, attendance rate, login count, average session duration, assignment submission rate, forum participation, and the count of educational videos watched. Preprocessing involved Min-Max normalization (Section 4.2) of features to a 0–1 scale, as well as Principal Component Analysis (PCA) (Section 4.3) to extract features with higher correlation to academic performance. The objective of this technique (PCA) was to reduce the dimensionality of complex data and identify the variables with the greatest influence on academic performance. | K6: Academic records, Demographic data, VLE activity log | L6: The AGTO-ResRNN model integrated the AGTO optimizer—inspired by the social dynamics and intelligent group behaviors of gorillas—with the ResRNN neural network. AGTO simulated the complex interactions of these primates, such as migrating to new locations (exploration), following the silverback leader, or competing for females (exploitation), to fine-tune hyperparameters and feature weights, thereby ensuring greater stability and convergence for the system. ResRNN, which incorporates residual error into an RNN layer, was responsible for capturing sequential patterns and long-term dependencies in student behavior and academic performance. By utilizing residual connections that adopted the direct hidden state as a reference, the model mitigated the vanishing gradient problem, enabling deep temporal analysis. | M6: Deep learning | N6: The evaluated metrics were Mean Absolute Error (MAE), Root Mean Square Error (RMSE), Accuracy, Precision, Recall, and F1-Score. (Section 5.5) The MAE and RMSE metrics were compared against the conventional EMD-PSO-SVM model, whereas Accuracy, Precision, Recall, and F1-Score were compared against the CNN-GRU model. | O6: The model achieved a MAE of 0,116, RMSE of 0,183, Accuracy of 98,50%, Precision of 96,54%, Recall of 95,42%, and an F1-Score of 96,00%. Consequently, the proposed model outperformed the baseline models across all evaluated metrics. Furthermore, AGTO-ResRNN was deemed more interpretable and efficient than CNN-GRU and EMD-PSO-SVM due to its lower computational resource requirements. | P6: The authors acknowledged the limitation that the dataset used was tied to a single institution. For future research, they proposed validating the model across datasets from multiple institutions. | Q6: Model generalization | R6: In Section 4.1, "Data Collection", the authors explicitly stated that the collected data were anonymized.
A7: Investigating Demographic Features and their Connection to Performance, Predictions, and Fairness in EDM Models | B7: 10.5281/zenodo.14503515 | C7: Cohausz, Lea and Tschalzev, Andrej and Bartelt, Christian and Stuckenschmidt, Heiner | D7: December 16, 2024 | E7: Scopus, Journal of Educational Data Mining, Zenodo | F7: Germany | G7: This study builds upon the work of Cohausz et al., Investigating the Importance of Demographic Features for EDM-Predictions (2023). Specifically, this follow-up study uses the demographic parity metric to evaluate the impact of demographic features on algorithmic bias. | H7: Consistent with the previous study (Cohausz et al., 2023). | I7: Hybrid | J7: Consistent with the previous study (Cohausz et al., 2023). | K7: Academic records, Demographic data | L7: Consistent with the previous study (Cohausz et al., 2023). | M7: Ensemble learning | N7: Consistent with the previous study (Cohausz et al., 2023). | O7: The central conclusion of the article regarding the analysis of Demographic Parity (DP) is that simply removing demographic features from models—a strategy known as "fairness through unawareness"—does not guarantee the elimination of bias and generally does not substantially alter equity levels measured by this metric. | P7: Consistent with the previous study (Cohausz et al., 2023). | Q7: Privacy concerns | R7: Consistent with the previous study (Cohausz et al., 2023).
A8: Assessment of civic education in universities from a multidimensional perspective: the Integration of OBE and CIPP models | B8: 10.1504/IJICT.2024.143413 | C8: Zhu, Yimin | D8: December 18, 2024 | E8: Scopus, International Journal of Information and Communication Technology, Inderscience Publishers | F8: China | G8: The authors propose an intelligent, multidimensional validation framework based on big data and machine learning that combines the theoretical models of Outcome-Based Education (OBE) and Context, Input, Process, and Product (CIPP). To evaluate civic education (ideological and political) in higher education, the framework integrates predictive machine learning models (Random Forest, SVM, LSTM, and GBM), a meta-model (Logistic Regression) derived from stacking the individual models, and a multimodal data fusion approach. | H8: The study utilized four data sources: 1.000 online learning records, 1.000 survey responses, 5.000 social media comments, and 1.000 teacher evaluation records. Eighty percent of the data was used for training, while the remaining 20% was used for evaluation. | I8: Online | J8: The variables are specified in Table 1 and were grounded in the CIPP model, comprising: Context (student demographics, learning environment resources, and sociocultural factors); Input (quality of instructional materials, faculty resources, and teaching competencies); Process (student actions and instructional activities tracked through learning logs and participation); and Product (final outcomes, such as ideological growth and learning achievement). Within this framework, CIPP provides the raw data and contextual foundation, whereas OBE establishes the success metrics for validating the objectives. | K8: Academic records, Demographic data, VLE activity log | L8: The framework incorporates Random Forest, SVM, LSTM, and GBM models, alongside two meta-models based on weighted and cascaded fusion of the individual model outputs. The proposed framework is grounded in two theoretical models. First, OBE establishes goals and measures achievements through quantitative metrics. The overall score is calculated as the sum of the goals weighted by their respective coefficients, which are determined via correlation analysis and technical expertise. Furthermore, the implementation of the OBE model enables the assessment of learning trends using linear regression on monitored learning progress over time. Second, CIPP structures the data dimensions: context analysis examines student perspectives and the learning environment; input evaluation assesses course material resources and teaching tools; process evaluation tracks student actions and instructional activities; and product evaluation measures student learning outcomes and ideological | M8: Ensemble learning | N8: Model performance was evaluated using Accuracy, Precision, Recall, and F1-Score. Both the standalone machine learning models and the meta-models were assessed, and their results were systematically compared. | O8: The evaluation results for the machine learning techniques are presented in Figure 3. Experimental findings demonstrate that the LSTM model achieved the highest accuracy and F1-score, excelling in the processing of complex sequential data. SVM and GBM also performed well, whereas Random Forest yielded the lowest performance. Finally, the authors maximized evaluation performance by leveraging the complementary strengths of the various machine learning models through a fusion experiment incorporating both weighted and cascaded approaches. The results indicate that the cascaded fusion meta-model achieved superior performance across all evaluated metrics, enabling significantly more comprehensive and reliable decision support than either traditional methods or individual standalone models. | P8: The authors acknowledge that the dataset was collected from a single institution. For future research, they suggest expanding the dataset with data gathered from additional institutions, as well as evaluating alternative machine learning models. | Q8: Model generalization | R8: The authors did not address any ethical or privacy implications.
A9: Predicting Student Dropout Rates in Massive Open Online Courses Using an Attention-Based GCNN Model | B9: 10.1109/ICECCC61767.2024.10593955 | C9: Balachandar, S. and Mann, Shikha and Thangam, A. and Dubey, Vivek Ravishankar and Bindu, V. and Nishant, Neerav | D9: Date of Conference: 02-03 May 2024; Date Added to IEEE Xplore: 23 July 2024 | E9: Scopus, 2024 International Conference on Electronics, Computing, Communication and Control Technology (ICECCC), IEEE | F9: India | G9: This study evaluates the performance of the Attention-Based Graph Convolutional Neural Network (A-GCNN) in predicting student dropout in higher education, with a focus on Massive Open Online Courses (MOOCs). | H9: Data were extracted from a dataset provided by a public online university in the United States, although the sample size was not specified. Appropriate preprocessing steps were performed, including the removal of tuples with missing critical values and the identification of significant features (or variables) based on their positive or negative impact on model performance during training, specifically through permutation testing with random weights. | I9: Online | J9: Section 3.2: Gender, prior academic performance, and engagement in classroom activities, including assignments, quizzes, and presentations. | K9: Academic records, Demographic data, VLE activity log | L9: Attention-Based Graph Convolutional Neural Network (A-GCNN). | M9: Deep learning | N9: Precision, recall, F1-score, and accuracy metrics were evaluated. | O9: Table 1: Performance comparison between the proposed model (A-GCNN) and baseline models (GCNN and A-CNN). The proposed A-GCNN achieved superior performance across all evaluated metrics: 96,6% Precision, 92,3% Recall, 98,7% F1-score, and 97,2% Accuracy. | P9: The authors report limitations regarding the available data, explaining the removal of tuples with data from students who dropped out of the course before completing two semesters. In this context, predicting this group of students represents a critical methodological gap for the study in question. | Q9: Class imbalance, Data availability | R9: The authors do not discuss ethical and privacy issues, nor do they address the informed consent of the students included in the dataset.
A10: IntelliDaM: A Machine Learning-Based Framework for Enhancing the Performance of Decision-Making Processes. A Case Study for Educational Data Mining | B10: 10.1109/ACCESS.2022.3195531 | C10: Czibula, Gabriela and Ciubotariu, George and Maier, Mariana-Ioana and Lisei, Hannelore | D10: August 1, 2022 | E10: Scopus, IEEE Access, IEEE | F10: Romania | G10: This study aims to design a framework based on data mining and machine learning—named IntelliDam—to extract information related to student performance in a real-world case study, as well as to analyze the effectiveness of this structure. It seeks to identify the relevance of data patterns uncovered through unsupervised learning from academic datasets and determine the extent to which these patterns correlate with student achievement. Furthermore, it investigates the importance of the features used in model training and their impact on predictive performance while assessing how performance prediction could be enhanced by incorporating students' results from prerequisite courses as additional training features. | H10: The dataset was collected from the Logic and Functional Programming course, offered in the third semester of the second year of the Mathematics and Computer Science program at Babeş-Bolyai University. The dataset comprised two case studies, totaling 506 instances (Table 3): records collected from the 2018–2019 and 2019–2020 cohorts (in-person), as well as the 2021–2022 cohort (COVID-19 pandemic, thus online). Section 4.A1: The collected data included assignment scores (1–7), practical exam grades (8–9, for Prolog and Lisp, respectively), seminar activity marks (10), attendance across the 7 seminars (11), the final grade in the prerequisite Data Structures and Algorithms course (12), and the final grade in the prerequisite Fundamentals of Programming course (13). For the pandemic period data, only the practical exams (8–9) were not administered. | I10: Hybrid | J10: Section 4.B: Details experiments with five feature configurations (LFP+DSA+FP, LFP+FP, LFP+DSA, LFP, and Relief-based) across two datasets to evaluate the impact of variables on predictive performance. These combinations were applied in supervised and unsupervised models to validate the importance of prerequisites and optimized features via ReliefF. | K10: Academic records | L10: The proposed model uses two learning approaches: in unsupervised learning, the model deals with the issue of student performance analysis by clustering students into performance categories—which can be divided into 7 classes (grades from 4 to 10, where 4 corresponds to failure) or 5 classes (Excellent, Very Good, Good, Satisfactory, and Fail)—using dimensionality reduction methods (t-SNE and UMAP) and the k-means algorithm (Section 3.C). In supervised learning, the authors deal with the problem of student performance prediction, treated here as a regression task. This means that the model estimates a continuous value for the final grade, which is later converted into categories for evaluation purposes. The model implements three main regressors (Section 3.D): Tweedie Regressor, Stochastic Gradient Descent, and Poly (Polynomial Regressor). Finally, the framework was implemented using the scikit and skrebate libraries. | M10: Machine learning | N10: For the supervised learning model, regression metrics (RMSE and NRMSE) and classification metrics (Accuracy, Precision, Recall, and F1-Score) were measured, as described in Section 3.D1. For the unsupervised model, external evaluation metrics were used, which compare the clusters formed by the model with the ground truth labels: Homogeneity, Completeness, and V-measure (Section 3.C1). While classification and clustering metrics indicate better performance when closer to 1, regression metrics (RMSE and NRMSE) indicate higher accuracy when values are lower (closer to 0), representing a smaller error. | O10: The framework's feature analysis used Pearson and Spearman coefficients (Figure 2) to identify the variables with the highest correlation with academic success. For unsupervised learning, the results are visible in Table 6 and Figures 3 and 4, demonstrating that students with similar performance tend to be naturally grouped by the system, revealing consistent learning patterns. In supervised learning (Tables 7 and 8), the polynomial regression model (Poly) presented the best results across all tested scenarios. Predictive performance was significantly optimized by the use of the Relief-based technique and the inclusion of grades from prerequisite courses. Finally, the authors identified that learning patterns were similar in both face-to-face and online environments, although the system faces challenges in accurately predicting the fail class due to external/unpredictable factors. | P10: Circumstances on the exam day, such as stress or poor emotional management, are cited as barriers that machine learning models have difficulty capturing. The system faced significant difficulties in accurately predicting the fail class. | Q10: Class imbalance | R10: The authors did not address the implications of ethical or privacy issues regarding the developed system, nor the informed consent of the students who comprised the dataset.
A11: Design and Implementation of an Intelligent Diagnostic System for Academic Performance Analysis in Medical Education | B11: 10.3390/electronics15132801 | C11: Aucancela, Margarita and González-Briones, Alfonso and Chamoso, Pablo | D11: June 25, 2026 | E11: Scopus, electronics, MDPI | F11: Spain | G11: Dual MLM-RF Framework: Decomposes population-level variance (MLM) while maintaining high-precision individual scoring (RF); Operational XAI: Development of a SHAP-based Priority Index that fuses inferential and predictive weights; Streamlit Deployment: Implementation of a functional prototype featuring Natural Language Clinical Directives for non-technical tutors; Methodological Transparency: Explicit reporting of encoding impacts and MAE parity ratios for algorithmic fairness. | H11: In-person environment: 18.604 longitudinal records; 1.264 unique students. | I11: In-person | J11: Academic: Academic period, curricular level, and course; Sociodemographic: Gender, province of origin, and student age (log-transformed). | K11: Academic records, Demographic data | L11: Random Forest: Optimized with 300 estimators and a depth of 15; selected for capturing non-linear interactions; 3-Level MLM: Primary inferential analyzer used to decompose variance across students and time; Secondary Baselines: XGBoost, Ridge Regression, and Multilayer Perceptron (MLP). | M11: Ensemble learning | N11: MAE, RMSE, R² for regression; Sensitivity, Specificity, AUC-ROC for classification. | O11: Performance metrics for Random Forest (best-performing): Regression: MAE 1,267 ± 0,04; RMSE 1,714 ± 0,05; R² 0,551 ± 0,02; and Classification: Sensitivity 0,532; Specificity 0,940; AUC-ROC 0,903. | P11: Scope: Single-institution context limits immediate external generalization; Behavioral Gap: Absence of LMS behavioral data (clickstream) limits sensitivity (0,532); Data Depth: Lack of section-level or instructor-level identifiers; Validation: Absence of temporal (future-period) cross-validation; Operational: Horizontal scaling costs for real-time SHAP computation in high-concurrent environments. | Q11: Data availability, Model generalization, Resource overhead | R11: The authors implemented an anonymization protocol and quantified fairness through MAE parity ratios. The results indicate equitable performance for 21 of 22 provinces, ensuring the model does not disproportionately penalize structurally vulnerable groups.
